2019-06-14 15:15:13,455 [ERROR]  Exception occurred while handling uri: 'http://0.0.0.0:5005/'
Traceback (most recent call last):
  File "/usr/local/lib/python3.6/site-packages/sanic/app.py", line 893, in handle_request
    handler, args, kwargs, uri = self.router.get(request)
  File "/usr/local/lib/python3.6/site-packages/sanic/router.py", line 407, in get
    return self._get(request.path, request.method, "")
  File "/usr/local/lib/python3.6/site-packages/sanic/router.py", line 469, in _get
    raise NotFound("Requested URL {} not found".format(url))
sanic.exceptions.NotFound: Requested URL / not found
2019-06-14 15:15:13,906 [ERROR]  Exception occurred while handling uri: 'http://0.0.0.0:5005/favicon.ico'
Traceback (most recent call last):
  File "/usr/local/lib/python3.6/site-packages/sanic/app.py", line 893, in handle_request
    handler, args, kwargs, uri = self.router.get(request)
  File "/usr/local/lib/python3.6/site-packages/sanic/router.py", line 407, in get
    return self._get(request.path, request.method, "")
  File "/usr/local/lib/python3.6/site-packages/sanic/router.py", line 469, in _get
    raise NotFound("Requested URL {} not found".format(url))
sanic.exceptions.NotFound: Requested URL /favicon.ico not found
2019-06-15 13:11:21,286 [ERROR]  Exception occurred while handling uri: 'http://localhost:5005/'
Traceback (most recent call last):
  File "/usr/local/lib/python3.6/site-packages/sanic/app.py", line 893, in handle_request
    handler, args, kwargs, uri = self.router.get(request)
  File "/usr/local/lib/python3.6/site-packages/sanic/router.py", line 407, in get
    return self._get(request.path, request.method, "")
  File "/usr/local/lib/python3.6/site-packages/sanic/router.py", line 469, in _get
    raise NotFound("Requested URL {} not found".format(url))
sanic.exceptions.NotFound: Requested URL / not found
2019-06-15 15:49:22,316 [ERROR]  Exception occurred while handling uri: 'http://localhost:5005/'
Traceback (most recent call last):
  File "/usr/local/lib/python3.6/site-packages/sanic/app.py", line 893, in handle_request
    handler, args, kwargs, uri = self.router.get(request)
  File "/usr/local/lib/python3.6/site-packages/sanic/router.py", line 407, in get
    return self._get(request.path, request.method, "")
  File "/usr/local/lib/python3.6/site-packages/sanic/router.py", line 469, in _get
    raise NotFound("Requested URL {} not found".format(url))
sanic.exceptions.NotFound: Requested URL / not found
2019-06-15 15:50:00,419 [ERROR]  Exception occurred while handling uri: 'http://localhost:5005/'
Traceback (most recent call last):
  File "/usr/local/lib/python3.6/site-packages/sanic/app.py", line 893, in handle_request
    handler, args, kwargs, uri = self.router.get(request)
  File "/usr/local/lib/python3.6/site-packages/sanic/router.py", line 407, in get
    return self._get(request.path, request.method, "")
  File "/usr/local/lib/python3.6/site-packages/sanic/router.py", line 469, in _get
    raise NotFound("Requested URL {} not found".format(url))
sanic.exceptions.NotFound: Requested URL / not found
2019-06-15 15:58:08,253 [ERROR]  Exception occurred in one of response middleware handlers
Traceback (most recent call last):
  File "/usr/local/lib/python3.6/site-packages/sanic/app.py", line 958, in handle_request
    request, response
  File "/usr/local/lib/python3.6/site-packages/spf/framework.py", line 543, in _run_response_middleware
    _response = await _response
  File "/usr/local/lib/python3.6/site-packages/sanic_cors/extension.py", line 266, in unapplied_cors_response_middleware
    set_cors_headers(req, resp, context, res_options)
  File "/usr/local/lib/python3.6/site-packages/sanic_cors/core.py", line 248, in set_cors_headers
    if resp.headers is None:
AttributeError: 'list' object has no attribute 'headers'
2019-06-15 16:01:26,952 [ERROR]  Exception occurred in one of response middleware handlers
Traceback (most recent call last):
  File "/usr/local/lib/python3.6/site-packages/sanic/app.py", line 958, in handle_request
    request, response
  File "/usr/local/lib/python3.6/site-packages/spf/framework.py", line 543, in _run_response_middleware
    _response = await _response
  File "/usr/local/lib/python3.6/site-packages/sanic_cors/extension.py", line 266, in unapplied_cors_response_middleware
    set_cors_headers(req, resp, context, res_options)
  File "/usr/local/lib/python3.6/site-packages/sanic_cors/core.py", line 248, in set_cors_headers
    if resp.headers is None:
AttributeError: 'list' object has no attribute 'headers'
